2024-03-23 17:25:32,937 INFO    MainThread:270401 [wandb_setup.py:_flush():76] Current SDK version is 0.16.4
2024-03-23 17:25:32,937 INFO    MainThread:270401 [wandb_setup.py:_flush():76] Configure stats pid to 270401
2024-03-23 17:25:32,937 INFO    MainThread:270401 [wandb_setup.py:_flush():76] Loading settings from /home/trangpvh1/.config/wandb/settings
2024-03-23 17:25:32,937 INFO    MainThread:270401 [wandb_setup.py:_flush():76] Loading settings from /lustre/scratch/client/vinai/users/trangpvh1/repo/FAN/scripts/fan_vit/wandb/settings
2024-03-23 17:25:32,937 INFO    MainThread:270401 [wandb_setup.py:_flush():76] Loading settings from environment variables: {'api_key': '***REDACTED***'}
2024-03-23 17:25:32,937 INFO    MainThread:270401 [wandb_setup.py:_flush():76] Applying setup settings: {'_disable_service': False}
2024-03-23 17:25:32,937 INFO    MainThread:270401 [wandb_setup.py:_flush():76] Inferring run settings from compute environment: {'program_relpath': 'main.py', 'program_abspath': '/lustre/scratch/client/vinai/users/trangpvh1/repo/FAN/main.py', 'program': '/lustre/scratch/client/vinai/users/trangpvh1/repo/FAN/main.py'}
2024-03-23 17:25:32,939 INFO    MainThread:270401 [wandb_init.py:_log_setup():526] Logging user logs to /lustre/scratch/client/vinai/users/trangpvh1/repo/FAN/scripts/fan_vit/wandb/run-20240323_172532-dpev7ujy/logs/debug.log
2024-03-23 17:25:32,939 INFO    MainThread:270401 [wandb_init.py:_log_setup():527] Logging internal logs to /lustre/scratch/client/vinai/users/trangpvh1/repo/FAN/scripts/fan_vit/wandb/run-20240323_172532-dpev7ujy/logs/debug-internal.log
2024-03-23 17:25:32,939 INFO    MainThread:270401 [wandb_init.py:init():566] calling init triggers
2024-03-23 17:25:32,939 INFO    MainThread:270401 [wandb_init.py:init():573] wandb.init called with sweep_config: {}
config: {}
2024-03-23 17:25:32,939 INFO    MainThread:270401 [wandb_init.py:init():616] starting backend
2024-03-23 17:25:32,940 INFO    MainThread:270401 [wandb_init.py:init():620] setting up manager
2024-03-23 17:25:32,944 INFO    MainThread:270401 [backend.py:_multiprocessing_setup():105] multiprocessing start_methods=fork,spawn,forkserver, using: spawn
2024-03-23 17:25:32,945 INFO    MainThread:270401 [wandb_init.py:init():628] backend started and connected
2024-03-23 17:25:32,947 INFO    MainThread:270401 [wandb_init.py:init():720] updated telemetry
2024-03-23 17:25:32,985 INFO    MainThread:270401 [wandb_init.py:init():753] communicating run to backend with 90.0 second timeout
2024-03-23 17:25:43,542 INFO    Thread-1  :270401 [retry.py:__call__():172] Retry attempt failed:
Traceback (most recent call last):
  File "/home/trangpvh1/envs/anaconda3/envs/fan_new/lib/python3.8/site-packages/urllib3/connectionpool.py", line 779, in urlopen
    self._prepare_proxy(conn)
  File "/home/trangpvh1/envs/anaconda3/envs/fan_new/lib/python3.8/site-packages/urllib3/connectionpool.py", line 1048, in _prepare_proxy
    conn.connect()
  File "/home/trangpvh1/envs/anaconda3/envs/fan_new/lib/python3.8/site-packages/urllib3/connection.py", line 633, in connect
    self._tunnel()  # type: ignore[attr-defined]
  File "/home/trangpvh1/envs/anaconda3/envs/fan_new/lib/python3.8/http/client.py", line 905, in _tunnel
    raise OSError("Tunnel connection failed: %d %s" % (code,
OSError: Tunnel connection failed: 403 VG-Blockpage

The above exception was the direct cause of the following exception:

urllib3.exceptions.ProxyError: ('Unable to connect to proxy', OSError('Tunnel connection failed: 403 VG-Blockpage'))

The above exception was the direct cause of the following exception:

Traceback (most recent call last):
  File "/home/trangpvh1/envs/anaconda3/envs/fan_new/lib/python3.8/site-packages/requests/adapters.py", line 486, in send
    resp = conn.urlopen(
  File "/home/trangpvh1/envs/anaconda3/envs/fan_new/lib/python3.8/site-packages/urllib3/connectionpool.py", line 847, in urlopen
    retries = retries.increment(
  File "/home/trangpvh1/envs/anaconda3/envs/fan_new/lib/python3.8/site-packages/urllib3/util/retry.py", line 515, in increment
    raise MaxRetryError(_pool, url, reason) from reason  # type: ignore[arg-type]
urllib3.exceptions.MaxRetryError: HTTPSConnectionPool(host='api.wandb.ai', port=443): Max retries exceeded with url: /graphql (Caused by ProxyError('Unable to connect to proxy', OSError('Tunnel connection failed: 403 VG-Blockpage')))

During handling of the above exception, another exception occurred:

Traceback (most recent call last):
  File "/home/trangpvh1/envs/anaconda3/envs/fan_new/lib/python3.8/site-packages/wandb/sdk/lib/retry.py", line 131, in __call__
    result = self._call_fn(*args, **kwargs)
  File "/home/trangpvh1/envs/anaconda3/envs/fan_new/lib/python3.8/site-packages/wandb/sdk/internal/internal_api.py", line 369, in execute
    return self.client.execute(*args, **kwargs)  # type: ignore
  File "/home/trangpvh1/envs/anaconda3/envs/fan_new/lib/python3.8/site-packages/wandb/vendor/gql-0.2.0/wandb_gql/client.py", line 52, in execute
    result = self._get_result(document, *args, **kwargs)
  File "/home/trangpvh1/envs/anaconda3/envs/fan_new/lib/python3.8/site-packages/wandb/vendor/gql-0.2.0/wandb_gql/client.py", line 60, in _get_result
    return self.transport.execute(document, *args, **kwargs)
  File "/home/trangpvh1/envs/anaconda3/envs/fan_new/lib/python3.8/site-packages/wandb/sdk/lib/gql_request.py", line 58, in execute
    request = self.session.post(self.url, **post_args)
  File "/home/trangpvh1/envs/anaconda3/envs/fan_new/lib/python3.8/site-packages/requests/sessions.py", line 637, in post
    return self.request("POST", url, data=data, json=json, **kwargs)
  File "/home/trangpvh1/envs/anaconda3/envs/fan_new/lib/python3.8/site-packages/requests/sessions.py", line 589, in request
    resp = self.send(prep, **send_kwargs)
  File "/home/trangpvh1/envs/anaconda3/envs/fan_new/lib/python3.8/site-packages/requests/sessions.py", line 703, in send
    r = adapter.send(request, **kwargs)
  File "/home/trangpvh1/envs/anaconda3/envs/fan_new/lib/python3.8/site-packages/requests/adapters.py", line 513, in send
    raise ProxyError(e, request=request)
requests.exceptions.ProxyError: HTTPSConnectionPool(host='api.wandb.ai', port=443): Max retries exceeded with url: /graphql (Caused by ProxyError('Unable to connect to proxy', OSError('Tunnel connection failed: 403 VG-Blockpage')))
